2022-05-26 16:24:27,054 INFO    MainThread:1198314 [internal.py:wandb_internal():88] W&B internal server running at pid: 1198314, started at: 2022-05-26 16:24:27.054050
2022-05-26 16:24:27,059 DEBUG   HandlerThread:1198314 [handler.py:handle_request():101] handle_request: check_version
2022-05-26 16:24:27,059 DEBUG   SenderThread:1198314 [sender.py:send():122] send: header
2022-05-26 16:24:27,060 DEBUG   SenderThread:1198314 [sender.py:send():122] send: request
2022-05-26 16:24:27,060 DEBUG   SenderThread:1198314 [sender.py:send_request():131] send_request: check_version
2022-05-26 16:24:27,059 INFO    WriterThread:1198314 [datastore.py:open_for_write():77] open: /data/Documents/cursos/nanodegree_ml_devops/nd0821-c2-build-model-workflow-exercises/lesson-4-training-validation-experiment-tracking/exercises/exercise_11/starter/random_forest/wandb/run-20220526_162426-2aj100le/run-2aj100le.wandb
2022-05-26 16:24:27,402 DEBUG   SenderThread:1198314 [sender.py:send():122] send: run
2022-05-26 16:24:56,644 ERROR   SenderThread:1198314 [internal_api.py:execute():126] 409 response executing GraphQL.
2022-05-26 16:24:56,645 ERROR   SenderThread:1198314 [internal_api.py:execute():127] {"errors":[{"message":"Error 1062: Duplicate entry '972751-2aj100le' for key 'PRIMARY'","path":["upsertBucket"]}],"data":{"upsertBucket":null}}
2022-05-26 16:24:56,645 ERROR   SenderThread:1198314 [retry.py:__call__():111] Retry attempt failed:
Traceback (most recent call last):
  File "/home/mateus/miniconda3/envs/mlflow-dbcbaa816e6f9957cfa4b70dff9ee8010f251acc/lib/python3.8/site-packages/wandb/old/retry.py", line 96, in __call__
    result = self._call_fn(*args, **kwargs)
  File "/home/mateus/miniconda3/envs/mlflow-dbcbaa816e6f9957cfa4b70dff9ee8010f251acc/lib/python3.8/site-packages/wandb/sdk/internal/internal_api.py", line 129, in execute
    six.reraise(*sys.exc_info())
  File "/home/mateus/miniconda3/envs/mlflow-dbcbaa816e6f9957cfa4b70dff9ee8010f251acc/lib/python3.8/site-packages/six.py", line 719, in reraise
    raise value
  File "/home/mateus/miniconda3/envs/mlflow-dbcbaa816e6f9957cfa4b70dff9ee8010f251acc/lib/python3.8/site-packages/wandb/sdk/internal/internal_api.py", line 123, in execute
    return self.client.execute(*args, **kwargs)
  File "/home/mateus/miniconda3/envs/mlflow-dbcbaa816e6f9957cfa4b70dff9ee8010f251acc/lib/python3.8/site-packages/wandb/vendor/gql-0.2.0/gql/client.py", line 52, in execute
    result = self._get_result(document, *args, **kwargs)
  File "/home/mateus/miniconda3/envs/mlflow-dbcbaa816e6f9957cfa4b70dff9ee8010f251acc/lib/python3.8/site-packages/wandb/vendor/gql-0.2.0/gql/client.py", line 60, in _get_result
    return self.transport.execute(document, *args, **kwargs)
  File "/home/mateus/miniconda3/envs/mlflow-dbcbaa816e6f9957cfa4b70dff9ee8010f251acc/lib/python3.8/site-packages/wandb/vendor/gql-0.2.0/gql/transport/requests.py", line 39, in execute
    request.raise_for_status()
  File "/home/mateus/miniconda3/envs/mlflow-dbcbaa816e6f9957cfa4b70dff9ee8010f251acc/lib/python3.8/site-packages/requests/models.py", line 960, in raise_for_status
    raise HTTPError(http_error_msg, response=self)
requests.exceptions.HTTPError: 409 Client Error: Conflict for url: https://api.wandb.ai/graphql
2022-05-26 16:24:57,403 DEBUG   HandlerThread:1198314 [handler.py:handle_request():101] handle_request: shutdown
2022-05-26 16:24:57,403 INFO    HandlerThread:1198314 [handler.py:finish():535] shutting down handler
2022-05-26 16:24:57,413 INFO    WriterThread:1198314 [datastore.py:close():258] close: /data/Documents/cursos/nanodegree_ml_devops/nd0821-c2-build-model-workflow-exercises/lesson-4-training-validation-experiment-tracking/exercises/exercise_11/starter/random_forest/wandb/run-20220526_162426-2aj100le/run-2aj100le.wandb
2022-05-26 16:25:02,153 INFO    SenderThread:1198314 [sender.py:_start_run_threads():596] run started: 2aj100le with start time 1653593066
2022-05-26 16:25:02,153 INFO    SenderThread:1198314 [sender.py:finish():833] shutting down sender
2022-05-26 16:25:10,973 INFO    MainThread:1198314 [internal.py:handle_exit():78] Internal process exited
